Workbook

Sheet Read Me
B2: Portillo Roofing - Site Skeleton, Keyword & Schema Map (v3, council-reviewed)
B3: 2026-10-09 (v3.1: owner answers applied - founded 2025, 25+ yrs experience; testimonials not real; TXST = San Marcos). Reviewed by a 4-seat council (local SEO, AI search, owner economics, red team). Nothing on the website has been changed yet.
B5: Start here
B6: 1. Phase 0 - Fix First: legal/accuracy problems on the LIVE site. These come before any new page.
B7: 2. Off-site Entity: the work that drives map-pack and AI answers more than pages do.
B8: 3. Page Map: the build list. Phase 1 = 25 pages (18 new, 7 existing reworked). Everything else is Planned, Section or Gated.
B9: 4. Council Log: what each reviewer said and what was adopted or overridden.
B11: Legend
B12: Yellow fill = you confirm or fill in (Offered?, Proof on hand, Completed jobs per town, min job size, Keyword Planner numbers, AI baseline results).
B13: Status: Live = exists | Draft = content exists, page not built | Planned = build | Section = a block on its parent page, not its own URL | Gated = build ONLY once real proof exists.
B14: Phase: 1 = first build | 2 = next | 3 = only when earned.
B15: Proof on hand: Y / N / ?. A quoted or in-progress job is not proof.
... B27: Without ad spend you get ranges ('10-100'); I'll convert to midpoints. 'Near me' and 'best ...' terms track demand only - they're won through GBP/reviews.

Sheet Phase 0 - Fix First
A1: # | B1: Severity | C1: Fix | D1: Where | E1: Why / source | F1: Owner | G1: Done?
A2: 1 | B2: Critical | C2: Remove competitor photos hotlinked through kimi-web-img.moonshot.cn and captioned as Portillo projects | D2: main: index.html:75,182,247,266,273,280; services.html:71,96,142,284; about.html:71,119; contact.html:69 (relaunch branch already removes them) | E2: Copyright + deceptive advertising; contradicts 'real project photos'. | F2: Claude (hotfix branch, your approval)
A3: 2 | B3: Critical | C3: Remove the three testimonials (Sarah Johnson, Mike Rodriguez, Jennifer Chen) - owner confirmed NOT real | D3: main: index.html ~300-336 | E3: FTC 16 CFR 465 (fake reviews/testimonials), civil penalties per violation. | F3: Claude Code
A4: 3 | B4: Critical | C4: Rewrite insurance copy: 'work directly with your insurance company to ensure you get fair coverage' + 'Direct insurance billing' | D4: main services.html:254,260; relaunch services.html:319,325 | E4: Tex. Ins. Code 4102.163: contractor may not act as or advertise as public adjuster; websites count as advertising (28 TAC 21.102). | F4: Claude drafts, Marco approves
A5: 4 | B5: Critical | C5: Add deductible notice to quote/contract template for insurance-funded jobs >= $1,000 | D5: quote system (generate_quote.js) | E5: Bus. & Com. Code 27.02; illegal to waive/absorb deductible. | F5: Claude (quote system)
A6: 5 | B6: High | C6: Use 'Founded 2025 - 25+ years of experience' everywhere; remove every '50+ years' and any '25+ years in business' wording (site, GBP, BBB, Yelp) | D6: relaunch index.html / about.html | E6: Owner confirmed: founded 2025, 25+ years experience. Conflicting facts get repeated by AI answers. | F6: Claude Code (site) / Marco (profiles)
A7: 6 | B7: High | C7: Remove or source '1000+ roofs', '5-star rating', 'Lifetime warranty', 'Licensed' | D7: relaunch index.html:100,104,170,262,366 | E7: Texas has no state roofing license; unsourced numbers flow into schema/AI copy. | F7: Marco confirm -> Claude
A8: 7 | B8: High | C8: Verify 'BBB Accredited' claim against live BBB profile | D8: relaunch index.html:308,320 | E8: Claim must be true. | F8: Marco
A9: 8 | B9: High | C9: Merge relaunch branch (after the fixes above) | D9: feature/crew-portfolio-update | E9: Portfolio + cleaned pages are stuck unmerged since Aug 8. | F9: Marco approves PR
A10: 9 | B10: High | C10: Render project pages as static HTML (not from portfolio-data.js) | D10: portfolio.html / portfolio-data.js | E10: Most AI crawlers don't run JavaScript. | F10: Claude
A11: 10 | B11: High | C11: Set up Google Search Console + Bing Webmaster Tools; submit sitemap; IndexNow ping on Netlify deploy | D11: DNS / Netlify | E11: ChatGPT search leans on Bing's index; GSC needed to measure anything. | F11: Marco (accounts) + Claude (config)
A12: 11 | B12: Medium | C12: robots.txt + sitemap.xml: allow Googlebot, Bingbot, OAI-SearchBot, ChatGPT-User, PerplexityBot | D12: repo root | E12: Allow search/answer crawlers; GPTBot / Google-Extended only govern training. | F12: Claude
A13: 12 | B13: Medium | C13: Build check: fail deploy if output HTML contains '[', 'TODO' or 'placeholder' | D13: repo build script | E13: Stops placeholders like '[year]' shipping. | F13: Claude
... A15: 14 | B15: Low | C15: noindex /thank-you/; 301 every old .html URL to its new folder URL | D15: _redirects | E15: Clean index; no broken links. | F15: Claude

Sheet Page Map
A1: ID | B1: Phase | C1: Status | D1: Surface | E1: Path | F1: Primary keyword (owns) | G1: Secondary keywords | H1: Intent | I1: Title tag (draft) | J1: Title len | K1: H1 / H2 (draft) | L1: Meta description (write by hand) | M1: Meta len | N1: Copy must include | O1: Schema (JSON-LD) | P1: Proof required before publishing | Q1: Proof on hand? | R1: Index | S1: Feeds (internal links) | T1: Monthly searches | U1: Notes
A2: P001 | B2: 1 | C2: Live | D2: Home | E2: / | F2: roofing contractor austin | G2: roofing company austin; roofers austin tx; best roofing company austin | H2: Commercial | I2: Austin Roofing Contractor | Portillo Roofing | J2: =IF(LEFT(I2,1)="(","",LEN(I2)) -> 44 | K2: Family-Owned Roofing Contractor for Austin & Central Texas | M2: =IF(L2="","",LEN(L2)) | N2: One location line used everywhere: 'Based in Dale, serving the Austin metro.' Facts line: 'Founded 2025 - 25+ years of roofing experience.' Never '25+ years in business' or '50+ years'. Real project photos only. No testimonials until real reviews exist. | O2: RoofingContractor + GeneralContractor (#org): foundingDate, address (Dale), telephone, areaServed [14 cities w/ Wikipedia sameAs], sameAs [GBP, BBB, Yelp, Facebook], hasOfferCatalog; WebSite | P2: Real photos; NAP; founding year (2025) | Q2: ? | R2: index | S2: All hubs, top roofing services, /projects/, /for-builders/ | T2: =SUMIF('Seed Keywords'!$C:$C,E2,'Seed Keywords'!$E:$E)+SUMIF('Seed Keywords'!$C:$C,E2&"#*",'Seed Keywords'!$E:$E) -> 0 | U2: 'best roofing company austin' is won by GBP/reviews/listicles, not a page - kept as a secondary here only. Fix Phase 0 items before anything else.
A3: P002 | B3: 1 | C3: Live | D3: Static | E3: /about/ | F3: family owned roofing company austin | H3: Navigational | I3: About Portillo Roofing - Family-Owned in Dale, TX | J3: =IF(LEFT(I3,1)="(","",LEN(I3)) -> 49 | K3: A Family Roofing Business, Built on the Roof | M3: =IF(L3="","",LEN(L3)) | N3: Founded 2025; 25+ years of hands-on roofing experience behind it (say whose); family history; crew (Arturo); real photos. | O3: AboutPage + Person (Marco Portillo, Marco Sr.) | P3: - | Q3: Y | R3: index | S3: /projects/, /contact/ | T3: =SUMIF('Seed Keywords'!$C:$C,E3,'Seed Keywords'!$E:$E)+SUMIF('Seed Keywords'!$C:$C,E3&"#*",'Seed Keywords'!$E:$E) -> 0 | U3: Live as about.html -> 301 to /about/.
A4: P003 | B4: 1 | C4: Live | D4: Static | E4: /contact/ | F4: portillo roofing contact | H4: Navigational | I4: Contact & Free Roof Inspection | Portillo Roofing | J4: =IF(LEFT(I4,1)="(","",LEN(I4)) -> 49 | K4: Request a Free Roof Inspection | M4: =IF(L4="","",LEN(L4)) | N4: Phone (512) 629-1342, email, hours, service-area zones. | O4: ContactPage | P4: - | Q4: Y | R4: index | S4: /areas/, /services/ | T4: =SUMIF('Seed Keywords'!$C:$C,E4,'Seed Keywords'!$E:$E)+SUMIF('Seed Keywords'!$C:$C,E4&"#*",'Seed Keywords'!$E:$E) -> 0 | U4: Live as contact.html -> 301.
A5: P004 | B5: 1 | C5: Planned | D5: Static | E5: /for-builders/ | F5: roofing subcontractor austin | H5: Commercial | I5: Roofing Subcontractor for Builders & GCs | Portillo Roofing | J5: =IF(LEFT(I5,1)="(","",LEN(I5)) -> 59 | K5: Roofing Subcontractor for Austin Builders & GCs | M5: =IF(L5="","",LEN(L5)) | N5: Capability sheet, not marketing: insurance (GL + workers' comp limits, COI on request); crew size + squares/week; lead time PO->start; systems (SnapLok, mechanical-lock, TPO, curved panels); references (Travis County, UT, TXST); supplier accounts / net terms / W-9 / lien waivers; one-field 'send plans for bid' form. | O5: Service + BreadcrumbList | P5: - | Q5: Y | R5: index | S5: /services/new-construction-roofing/, /services/commercial-roofing/, /projects/ | T5: =SUMIF('Seed Keywords'!$C:$C,E5,'Seed Keywords'!$E:$E)+SUMIF('Seed Keywords'!$C:$C,E5&"#*",'Seed Keywords'!$E:$E) -> 0 | U5: Serves the GC/builder channel.
A6: P005 | B6: 1 | C6: Planned | D6: Static | E6: /for-restoration/ | F6: restoration roofing subcontractor austin | H6: Commercial | I6: Roofing Partner for Restoration Companies | Portillo Roofing | J6: =IF(LEFT(I6,1)="(","",LEN(I6)) -> 60 | K6: Storm Overflow Roofing for Restoration Companies | M6: =IF(L6="","",LEN(L6)) | N6: Overflow capacity; response time after a storm; estimate format (Xactimate only if true); photo documentation standard; willingness to work under their brand; insurance on file. | O6: Service + BreadcrumbList | P6: - | Q6: Y | R6: index | S6: /services/hail-damage-roof-repair/, /projects/ | T6: =SUMIF('Seed Keywords'!$C:$C,E6,'Seed Keywords'!$E:$E)+SUMIF('Seed Keywords'!$C:$C,E6&"#*",'Seed Keywords'!$E:$E) -> 0 | U6: NEW (council). Serves restoration/insurance overflow channel. Ship before March.
A7: P006 | B7: 1 | C7: Live | D7: Hub | E7: /services/ | F7: roofing services austin | H7: Navigational | I7: Roofing Services in Austin, TX | Portillo Roofing | J7: =IF(LEFT(I7,1)="(","",LEN(I7)) -> 49 | K7: Roofing Services | M7: =IF(L7="","",LEN(L7)) | N7: 1-paragraph intro naming what's in the section; card per child page with photo; no thin filler. | O7: CollectionPage + BreadcrumbList | P7: - | Q7: Y | R7: index | S7: Every roofing service page | T7: =SUMIF('Seed Keywords'!$C:$C,E7,'Seed Keywords'!$E:$E)+SUMIF('Seed Keywords'!$C:$C,E7&"#*",'Seed Keywords'!$E:$E) -> 0 | U7: Live as services.html -> 301 to /services/. Becomes roofing-only hub (remodeling/countertops move out).
A8: P007 | B8: 1 | C8: Draft | D8: Hub | E8: /projects/ | F8: roofing projects austin | H8: Navigational | I8: Roofing Projects & Portfolio | Portillo Roofing | J8: =IF(LEFT(I8,1)="(","",LEN(I8)) -> 47 | K8: Our Work | M8: =IF(L8="","",LEN(L8)) | N8: 1-paragraph intro naming what's in the section; card per child page with photo; no thin filler. | O8: CollectionPage + BreadcrumbList | P8: - | Q8: Y | R8: index | S8: Every project page | T8: =SUMIF('Seed Keywords'!$C:$C,E8,'Seed Keywords'!$E:$E)+SUMIF('Seed Keywords'!$C:$C,E8&"#*",'Seed Keywords'!$E:$E) -> 0 | U8: portfolio.html on relaunch branch; must render project pages as static HTML.
A9: P008 | B9: 1 | C9: Planned | D9: Roofing service | E9: /services/roof-replacement/ | F9: roof replacement austin | G9: reroof austin; roof replacement company austin; new roof austin | H9: Transactional | I9: Roof Replacement in Austin, TX | Portillo Roofing | J9: =IF(LEFT(I9,1)="(","",LEN(I9)) -> 49 | K9: Roof Replacement in Austin & Central Texas | M9: =IF(L9="","",LEN(L9)) | N9: 40-60 word direct answer up top; dated $/square range from YOUR jobs + what moves it; specs (panel profile, gauge, underlayment, impact rating); typical duration; permit office; 2+ captioned project photos; 5-8 FAQs unique to this page; last-updated date. | O9: Service (provider #org, areaServed) + BreadcrumbList; FAQPage optional (no rich result) | P9: Photos of this service + process + FAQs. Evidence: TXST Apartments (400 sq reroof) | Q9: Y | R9: index | S9: Live city pages; Projects: TXST Apartments; Guides: roof-replacement-cost-austin, how-long-does-a-roof-last-in-texas, roofing-permit-austin, how-to-choose-a-roofer-austin, roof-replacement-timeline | T9: =SUMIF('Seed Keywords'!$C:$C,E9,'Seed Keywords'!$E:$E)+SUMIF('Seed Keywords'!$C:$C,E9&"#*",'Seed Keywords'!$E:$E) -> 0 | U9: Cost intent belongs to the cost guide - link to it, don't target it here.
A10: P009 | B10: 1 | C10: Planned | D10: Roofing service | E10: /services/roof-repair/ | F10: roof repair austin | G10: roof leak repair austin; roof repair company austin | H10: Transactional | I10: Roof Repair in Austin, TX | Portillo Roofing | J10: =IF(LEFT(I10,1)="(","",LEN(I10)) -> 44 | K10: Roof Repair in Austin & Central Texas | M10: =IF(L10="","",LEN(L10)) | N10: 40-60 word direct answer up top; dated $/square range from YOUR jobs + what moves it; specs (panel profile, gauge, underlayment, impact rating); typical duration; permit office; 2+ captioned project photos; 5-8 FAQs unique to this page; last-updated date. | O10: Service (provider #org, areaServed) + BreadcrumbList; FAQPage optional (no rich result) | P10: Photos of this service + process + FAQs. Evidence: Listed on current site - need repair job photos | Q10: ? | R10: index | S10: Live city pages | T10: =SUMIF('Seed Keywords'!$C:$C,E10,'Seed Keywords'!$E:$E)+SUMIF('Seed Keywords'!$C:$C,E10&"#*",'Seed Keywords'!$E:$E) -> 0 | U10: Owns '<service> austin'; no /areas/austin/ page. Cross-link to ceiling/drywall repair section after leaks.
A11: P010 | B11: 1 | C11: Planned | D11: Roofing service | E11: /services/metal-roofing/ | F11: metal roofing austin | G11: standing seam metal roof austin; metal roof contractor austin; custom metal fascia; curved standing seam panels | H11: Transactional | I11: Metal Roofing in Austin, TX | Portillo Roofing | J11: =IF(LEFT(I11,1)="(","",LEN(I11)) -> 46 | K11: Standing Seam Metal Roofing in Austin & Central Texas | M11: =IF(L11="","",LEN(L11)) | N11: 40-60 word direct answer up top; dated $/square range from YOUR jobs + what moves it; specs (panel profile, gauge, underlayment, impact rating); typical duration; permit office; 2+ captioned project photos; 5-8 FAQs unique to this page; last-updated date. | O11: Service (provider #org, areaServed) + BreadcrumbList; FAQPage optional (no rich result) | P11: Photos of this service + process + FAQs. Evidence: Inwood, Shoalwood, Knollwood, Curved Ridges, Yuapon | Q11: Y | R11: index | S11: Live city pages; Projects: Inwood, Curved Ridges, Yuapon; Guides: metal-roof-cost-austin, metal-vs-shingle-roof-texas, standing-seam-vs-exposed-fastener | T11: =SUMIF('Seed Keywords'!$C:$C,E11,'Seed Keywords'!$E:$E)+SUMIF('Seed Keywords'!$C:$C,E11&"#*",'Seed Keywords'!$E:$E) -> 0 | U11: Signature niche. Custom fabrication lives here as a section (see #custom-fabrication row).
A12: P011 | B12: 1 | C12: Planned | D12: Roofing service | E12: /services/flat-roofing/ | F12: tpo roofing austin | G12: flat roof repair austin; flat roof replacement austin | H12: Transactional | I12: Flat & TPO Roofing in Austin, TX | Portillo Roofing | J12: =IF(LEFT(I12,1)="(","",LEN(I12)) -> 51 | K12: Flat & TPO Roofing in Austin & Central Texas | M12: =IF(L12="","",LEN(L12)) | N12: 40-60 word direct answer up top; dated $/square range from YOUR jobs + what moves it; specs (panel profile, gauge, underlayment, impact rating); typical duration; permit office; 2+ captioned project photos; 5-8 FAQs unique to this page; last-updated date. | O12: Service (provider #org, areaServed) + BreadcrumbList; FAQPage optional (no rich result) | P12: Photos of this service + process + FAQs. Evidence: Mendez School (TPO), Knollwood | Q12: Y | R12: index | S12: Live city pages; Projects: Mendez School; Guides: tpo-vs-modified-bitumen | T12: =SUMIF('Seed Keywords'!$C:$C,E12,'Seed Keywords'!$E:$E)+SUMIF('Seed Keywords'!$C:$C,E12&"#*",'Seed Keywords'!$E:$E) -> 0 | U12: Check Planner: if 'flat roof repair austin' outranks 'tpo roofing austin', swap primary.
A13: P012 | B13: 1 | C13: Planned | D13: Roofing service | E13: /services/commercial-roofing/ | F13: commercial roofing austin | G13: commercial roofing contractor austin; commercial roof replacement austin; commercial tpo contractor | H13: Transactional | I13: Commercial Roofing in Austin, TX | Portillo Roofing | J13: =IF(LEFT(I13,1)="(","",LEN(I13)) -> 51 | K13: Commercial Roofing in Austin & Central Texas | M13: =IF(L13="","",LEN(L13)) | N13: 40-60 word direct answer up top; dated $/square range from YOUR jobs + what moves it; specs (panel profile, gauge, underlayment, impact rating); typical duration; permit office; 2+ captioned project photos; 5-8 FAQs unique to this page; last-updated date. | O13: Service (provider #org, areaServed) + BreadcrumbList; FAQPage optional (no rich result) | P13: Photos of this service + process + FAQs. Evidence: Travis County Jail, Mendez School, TXST, UT Batter's Eye | Q13: Y | R13: index | S13: Live city pages; Projects: Travis County Jail, UT Austin Batter's Eye | T13: =SUMIF('Seed Keywords'!$C:$C,E13,'Seed Keywords'!$E:$E)+SUMIF('Seed Keywords'!$C:$C,E13&"#*",'Seed Keywords'!$E:$E) -> 0 | U13: Council split: economics seat would merge with Flat/TPO. Kept separate (different buyer).
A14: P013 | B14: 1 | C14: Planned | D14: Roofing service | E14: /services/new-construction-roofing/ | F14: new construction roofing austin | G14: builder roofing contractor austin; new home roofing austin | H14: Transactional | I14: New Construction Roofing in Austin, TX | Portillo Roofing | J14: =IF(LEFT(I14,1)="(","",LEN(I14)) -> 57 | K14: New Construction Roofing in Austin & Central Texas | M14: =IF(L14="","",LEN(L14)) | N14: 40-60 word direct answer up top; dated $/square range from YOUR jobs + what moves it; specs (panel profile, gauge, underlayment, impact rating); typical duration; permit office; 2+ captioned project photos; 5-8 FAQs unique to this page; last-updated date. | O14: Service (provider #org, areaServed) + BreadcrumbList; FAQPage optional (no rich result) | P14: Photos of this service + process + FAQs. Evidence: Inwood, Shoalwood, Knollwood, Fiset | Q14: Y | R14: index | S14: Live city pages; Projects: Knollwood, Shoalwood, Fiset | T14: =SUMIF('Seed Keywords'!$C:$C,E14,'Seed Keywords'!$E:$E)+SUMIF('Seed Keywords'!$C:$C,E14&"#*",'Seed Keywords'!$E:$E) -> 0 | U14: 'roofing subcontractor austin' is owned by /for-builders/.
A15: P014 | B15: 1 | C15: Planned | D15: Roofing service | E15: /services/hail-damage-roof-repair/ | F15: hail damage roof repair austin | G15: storm damage roof repair austin; hail damage roof inspection; wind damage roof repair; insurance roof inspection austin | H15: Transactional | I15: Hail & Storm Damage Repair in Austin, TX | Portillo Roofing | J15: =IF(LEFT(I15,1)="(","",LEN(I15)) -> 59 | K15: Hail & Storm Damage Repair in Austin & Central Texas | M15: =IF(L15="","",LEN(L15)) | N15: COMPLIANCE (Ins. Code 4102.163; Bus. & Com. Code 27.02): OK to say inspect, photograph, write a repair scope, meet the adjuster on site as the contractor. NEVER say negotiate, represent you, fair coverage, maximize your claim, direct insurance billing, or anything about covering/waiving the deductible. Include a plain statement that the homeowner pays their deductible. 40-60 word direct answer up top; dated $/square range from YOUR jobs + what moves it; specs (panel profile, gauge, underlayment, impact rating); typical duration; permit office; 2+ captioned project photos; 5-8 FAQs unique to this page; last-updated date. | O15: Service (provider #org, areaServed) + BreadcrumbList; FAQPage optional (no rich result) | P15: Photos of this service + process + FAQs. Evidence: Listed on current site - need storm job photos | Q15: ? | R15: index | S15: Live city pages; Guides: does-insurance-cover-hail-damage-texas, signs-of-hail-damage-on-roof | T15: =SUMIF('Seed Keywords'!$C:$C,E15,'Seed Keywords'!$E:$E)+SUMIF('Seed Keywords'!$C:$C,E15&"#*",'Seed Keywords'!$E:$E) -> 0 | U15: Merged with old 'Roof Insurance Claim Help' page. COMPLIANCE: see Copy column. Ship before March (hail season).
A16: P015 | B16: 1 | C16: Section | D16: Section | E16: /services/metal-roofing/#custom-fabrication | F16: custom metal fascia austin | G16: curved standing seam roof; tapered metal fascia | H16: Transactional | I16: (section - uses parent page title) | J16: =IF(LEFT(I16,1)="(","",LEN(I16)) | K16: H2: Custom Metal Fascia & Curved Panels | M16: =IF(L16="","",LEN(L16)) | N16: Inside the parent page: H2 named for the service, 80-150 words, 2+ photos, price range or 'typical scope', link to contact. Promote to its own page when proof + volume justify it. | O16: None of its own - listed in parent page's Service / hasOfferCatalog | P16: Photos of this work. Evidence: Yuapon, Curved Ridges | Q16: Y | R16: index | S16: Parent: /services/metal-roofing/ | T16: =SUMIF('Seed Keywords'!$C:$C,E16,'Seed Keywords'!$E:$E)+SUMIF('Seed Keywords'!$C:$C,E16&"#*",'Seed Keywords'!$E:$E) -> 0 | U16: Category: Roofing.
A17: P016 | B17: 1 | C17: Planned | D17: City | E17: /areas/dale/ | F17: roofer dale | G17: roofing company dale; roofing contractor dale tx; roof repair dale | H17: Transactional | I17: Dale, TX Roofing Contractor | Portillo Roofing | J17: =IF(LEFT(I17,1)="(","",LEN(I17)) -> 46 | K17: Roofing Contractor in Dale, TX | M17: =IF(L17="","",LEN(L17)) | N17: Number of jobs completed in this town; 1+ project with photos; permit authority; housing stock / HOA notes; dated local hail events; what we take on in this zone; links to nearby towns. Never a find-and-replace of another town page. | O17: Service (provider #org, areaServed City) + BreadcrumbList. Never a separate business entity per town. | P17: >=1 completed job in town with photos (2+ preferred) | Q17: ? | R17: index | S17: Roofing services; live Service x City pages for this town; projects here; 2 nearest towns | T17: =SUMIF('Seed Keywords'!$C:$C,E17,'Seed Keywords'!$E:$E)+SUMIF('Seed Keywords'!$C:$C,E17&"#*",'Seed Keywords'!$E:$E) -> 0 | U17: Zone: South core (All services incl. add-ons). Home base - build first; still needs local job photos.
A18: P017 | B18: 1 | C18: Planned | D18: City | E18: /areas/san-marcos/ | F18: roofer san marcos | G18: roofing company san marcos; roofing contractor san marcos tx; roof repair san marcos | H18: Transactional | I18: San Marcos, TX Roofing Contractor | Portillo Roofing | J18: =IF(LEFT(I18,1)="(","",LEN(I18)) -> 52 | K18: Roofing Contractor in San Marcos, TX | M18: =IF(L18="","",LEN(L18)) | N18: Number of jobs completed in this town; 1+ project with photos; permit authority; housing stock / HOA notes; dated local hail events; what we take on in this zone; links to nearby towns. Never a find-and-replace of another town page. | O18: Service (provider #org, areaServed City) + BreadcrumbList. Never a separate business entity per town. | P18: >=1 completed job in town with photos (2+ preferred) | Q18: Y | R18: index | S18: Roofing services; live Service x City pages for this town; projects here; 2 nearest towns | T18: =SUMIF('Seed Keywords'!$C:$C,E18,'Seed Keywords'!$E:$E)+SUMIF('Seed Keywords'!$C:$C,E18&"#*",'Seed Keywords'!$E:$E) -> 0 | U18: Zone: South core (All services incl. add-ons). TXST Apartments 400-sq reroof (owner confirmed San Marcos).
A19: P018 | B19: 1 | C19: Draft | D19: Project | E19: /projects/travis-county-jail/ | F19: curved metal roof & steel frame project | H19: Proof | I19: Travis County Jail | Portillo Roofing | J19: =IF(LEFT(I19,1)="(","",LEN(I19)) -> 37 | K19: Travis County Jail: Curved Metal Roof & Steel Frame | M19: =IF(L19="","",LEN(L19)) | N19: City, year, squares, system/materials, client type (GC / owner / public), duration, problem -> fix, 6+ captioned photos, written photo consent. Must be static HTML (not loaded from portfolio-data.js). | O19: Article/CreativeWork (contentLocation, dateCreated, about -> Service, image[]) + BreadcrumbList | P19: Photos + scope write-up (exists in portfolio-data.js) + photo consent | Q19: Y | R19: index | S19: /services/commercial-roofing/; town page for job location | T19: =SUMIF('Seed Keywords'!$C:$C,E19,'Seed Keywords'!$E:$E)+SUMIF('Seed Keywords'!$C:$C,E19&"#*",'Seed Keywords'!$E:$E) -> 0 | U19: Need job town. GC jobs: get builder OK before publishing.
A20: P019 | B20: 1 | C20: Draft | D20: Project | E20: /projects/ut-austin-batters-eye/ | F20: removable metal panel system project | H20: Proof | I20: UT Austin Batter's Eye | Portillo Roofing | J20: =IF(LEFT(I20,1)="(","",LEN(I20)) -> 41 | K20: UT Austin Batter's Eye: Removable Metal Panel System | M20: =IF(L20="","",LEN(L20)) | N20: City, year, squares, system/materials, client type (GC / owner / public), duration, problem -> fix, 6+ captioned photos, written photo consent. Must be static HTML (not loaded from portfolio-data.js). | O20: Article/CreativeWork (contentLocation, dateCreated, about -> Service, image[]) + BreadcrumbList | P20: Photos + scope write-up (exists in portfolio-data.js) + photo consent | Q20: Y | R20: index | S20: /services/commercial-roofing/; town page for job location | T20: =SUMIF('Seed Keywords'!$C:$C,E20,'Seed Keywords'!$E:$E)+SUMIF('Seed Keywords'!$C:$C,E20&"#*",'Seed Keywords'!$E:$E) -> 0 | U20: Need job town. GC jobs: get builder OK before publishing.
A21: P020 | B21: 1 | C21: Draft | D21: Project | E21: /projects/inwood/ | F21: standing seam metal roof project | H21: Proof | I21: Inwood | Portillo Roofing | J21: =IF(LEFT(I21,1)="(","",LEN(I21)) -> 25 | K21: Inwood: Standing Seam Metal Roof | M21: =IF(L21="","",LEN(L21)) | N21: City, year, squares, system/materials, client type (GC / owner / public), duration, problem -> fix, 6+ captioned photos, written photo consent. Must be static HTML (not loaded from portfolio-data.js). | O21: Article/CreativeWork (contentLocation, dateCreated, about -> Service, image[]) + BreadcrumbList | P21: Photos + scope write-up (exists in portfolio-data.js) + photo consent | Q21: Y | R21: index | S21: /services/metal-roofing/; town page for job location | T21: =SUMIF('Seed Keywords'!$C:$C,E21,'Seed Keywords'!$E:$E)+SUMIF('Seed Keywords'!$C:$C,E21&"#*",'Seed Keywords'!$E:$E) -> 0 | U21: Need job town. GC jobs: get builder OK before publishing.
A22: P021 | B22: 1 | C22: Draft | D22: Project | E22: /projects/txst-apartments/ | F22: 400-square shingle reroof project | H22: Proof | I22: TXST Apartments | Portillo Roofing | J22: =IF(LEFT(I22,1)="(","",LEN(I22)) -> 34 | K22: TXST Apartments: 400-Square Shingle Reroof | M22: =IF(L22="","",LEN(L22)) | N22: City, year, squares, system/materials, client type (GC / owner / public), duration, problem -> fix, 6+ captioned photos, written photo consent. Must be static HTML (not loaded from portfolio-data.js). | O22: Article/CreativeWork (contentLocation, dateCreated, about -> Service, image[]) + BreadcrumbList | P22: Photos + scope write-up (exists in portfolio-data.js) + photo consent | Q22: Y | R22: index | S22: /services/roof-replacement/; town page for job location | T22: =SUMIF('Seed Keywords'!$C:$C,E22,'Seed Keywords'!$E:$E)+SUMIF('Seed Keywords'!$C:$C,E22&"#*",'Seed Keywords'!$E:$E) -> 0 | U22: Need job town. GC jobs: get builder OK before publishing.
A23: P022 | B23: 1 | C23: Draft | D23: Project | E23: /projects/mendez-school/ | F23: commercial tpo roof project | H23: Proof | I23: Mendez School | Portillo Roofing | J23: =IF(LEFT(I23,1)="(","",LEN(I23)) -> 32 | K23: Mendez School: Commercial TPO Roof | M23: =IF(L23="","",LEN(L23)) | N23: City, year, squares, system/materials, client type (GC / owner / public), duration, problem -> fix, 6+ captioned photos, written photo consent. Must be static HTML (not loaded from portfolio-data.js). | O23: Article/CreativeWork (contentLocation, dateCreated, about -> Service, image[]) + BreadcrumbList | P23: Photos + scope write-up (exists in portfolio-data.js) + photo consent | Q23: Y | R23: index | S23: /services/flat-roofing/; town page for job location | T23: =SUMIF('Seed Keywords'!$C:$C,E23,'Seed Keywords'!$E:$E)+SUMIF('Seed Keywords'!$C:$C,E23&"#*",'Seed Keywords'!$E:$E) -> 0 | U23: Need job town. GC jobs: get builder OK before publishing.
A24: P023 | B24: 1 | C24: Planned | D24: Guide | E24: /guides/roof-replacement-cost-austin/ | F24: roof replacement cost austin | G24: new roof cost austin; cost per square roofing austin | H24: Informational | I24: How Much Does a Roof Replacement Cost in Austin? | J24: =IF(LEFT(I24,1)="(","",LEN(I24)) -> 48 | K24: How Much Does a Roof Replacement Cost in Austin? | M24: =IF(L24="","",LEN(L24)) | N24: Byline (Marco Portillo + credentials); direct answer first; your own numbers; cited sources; last-updated date. | O24: Article (author Person w/ sameAs, dateModified) + BreadcrumbList | P24: Your own numbers / photos; byline | Q24: ? | R24: index | S24: /services/roof-replacement/ | T24: =SUMIF('Seed Keywords'!$C:$C,E24,'Seed Keywords'!$E:$E)+SUMIF('Seed Keywords'!$C:$C,E24&"#*",'Seed Keywords'!$E:$E) -> 0
A25: P024 | B25: 1 | C25: Live | D25: Utility | E25: /thank-you/ | F25: - | H25: - | I25: Thank You | Portillo Roofing | J25: =IF(LEFT(I25,1)="(","",LEN(I25)) -> 28 | K25: Thank You | M25: =IF(L25="","",LEN(L25)) | O25: - | P25: - | Q25: Y | R25: noindex | S25: - | T25: =SUMIF('Seed Keywords'!$C:$C,E25,'Seed Keywords'!$E:$E)+SUMIF('Seed Keywords'!$C:$C,E25&"#*",'Seed Keywords'!$E:$E) -> 0 | U25: Currently indexable - set noindex.
A26: P025 | B26: 1 | C26: Live | D26: Utility | E26: /privacy-policy/ | F26: - | H26: - | I26: Privacy Policy | Portillo Roofing | J26: =IF(LEFT(I26,1)="(","",LEN(I26)) -> 33 | K26: Privacy Policy | M26: =IF(L26="","",LEN(L26)) | O26: - | P26: - | Q26: Y | R26: index | S26: - | T26: =SUMIF('Seed Keywords'!$C:$C,E26,'Seed Keywords'!$E:$E)+SUMIF('Seed Keywords'!$C:$C,E26&"#*",'Seed Keywords'!$E:$E) -> 0
A27: P026 | B27: 1 | C27: Live | D27: Utility | E27: /terms-of-service/ | F27: - | H27: - | I27: Terms of Service | Portillo Roofing | J27: =IF(LEFT(I27,1)="(","",LEN(I27)) -> 35 | K27: Terms of Service | M27: =IF(L27="","",LEN(L27)) | O27: - | P27: - | Q27: Y | R27: index | S27: - | T27: =SUMIF('Seed Keywords'!$C:$C,E27,'Seed Keywords'!$E:$E)+SUMIF('Seed Keywords'!$C:$C,E27&"#*",'Seed Keywords'!$E:$E) -> 0
A28: P027 | B28: 2 | C28: Planned | D28: Static | E28: /reviews/ | F28: portillo roofing reviews | H28: Navigational | I28: Customer Reviews | Portillo Roofing | J28: =IF(LEFT(I28,1)="(","",LEN(I28)) -> 35 | K28: What Our Customers Say | M28: =IF(L28="","",LEN(L28)) | N28: Only real reviews with first name + town, linked to Google/BBB source. FTC 16 CFR 465 bans fake/AI testimonials. | O28: WebPage (no self-serving AggregateRating) | P28: - | Q28: Y | R28: index | S28: /projects/, /contact/ | T28: =SUMIF('Seed Keywords'!$C:$C,E28,'Seed Keywords'!$E:$E)+SUMIF('Seed Keywords'!$C:$C,E28&"#*",'Seed Keywords'!$E:$E) -> 0 | U28: Wait until 5+ real reviews.
A29: P028 | B29: 2 | C29: Planned | D29: Hub | E29: /remodeling/ | F29: remodeling contractor austin | H29: Navigational | I29: Remodeling & Home Services in Austin | Portillo Roofing | J29: =IF(LEFT(I29,1)="(","",LEN(I29)) -> 55 | K29: Remodeling, Painting & Exterior Services | M29: =IF(L29="","",LEN(L29)) | N29: 1-paragraph intro naming what's in the section; card per child page with photo; no thin filler. | O29: CollectionPage + BreadcrumbList | P29: - | Q29: Y | R29: index | S29: Remodeling pages + every section | T29: =SUMIF('Seed Keywords'!$C:$C,E29,'Seed Keywords'!$E:$E)+SUMIF('Seed Keywords'!$C:$C,E29&"#*",'Seed Keywords'!$E:$E) -> 0 | U29: One hub holds remodeling, painting, coatings, tile, drywall and pressure washing as sections (council: no separate hubs).
A30: P029 | B30: 2 | C30: Planned | D30: Hub | E30: /countertops/ | F30: custom countertops austin | H30: Navigational | I30: Custom Countertops in Austin, TX | Portillo Roofing | J30: =IF(LEFT(I30,1)="(","",LEN(I30)) -> 51 | K30: Granite, Epoxy & River Countertops | M30: =IF(L30="","",LEN(L30)) | N30: 1-paragraph intro naming what's in the section; card per child page with photo; no thin filler. | O30: CollectionPage + BreadcrumbList | P30: - | Q30: Y | R30: index | S30: Countertop sections | T30: =SUMIF('Seed Keywords'!$C:$C,E30,'Seed Keywords'!$E:$E)+SUMIF('Seed Keywords'!$C:$C,E30&"#*",'Seed Keywords'!$E:$E) -> 0 | U30: Specialty line as ONE page with sections; split a section out only when it earns it.
A31: P030 | B31: 2 | C31: Planned | D31: Hub | E31: /areas/ | F31: roofing service area central texas | H31: Navigational | I31: Service Areas - Central Texas | Portillo Roofing | J31: =IF(LEFT(I31,1)="(","",LEN(I31)) -> 48 | K31: Where We Work | M31: =IF(L31="","",LEN(L31)) | N31: 1-paragraph intro naming what's in the section; card per child page with photo; no thin filler. | O31: CollectionPage + BreadcrumbList | P31: - | Q31: Y | R31: index | S31: Every live city page | T31: =SUMIF('Seed Keywords'!$C:$C,E31,'Seed Keywords'!$E:$E)+SUMIF('Seed Keywords'!$C:$C,E31&"#*",'Seed Keywords'!$E:$E) -> 0 | U31: Lists all 14 towns with zones; links only to city pages that are live.
A32: P031 | B32: 2 | C32: Planned | D32: Hub | E32: /guides/ | F32: roofing guides texas | H32: Navigational | I32: Roofing Guides & Answers | Portillo Roofing | J32: =IF(LEFT(I32,1)="(","",LEN(I32)) -> 43 | K32: Roofing Questions, Answered | M32: =IF(L32="","",LEN(L32)) | N32: 1-paragraph intro naming what's in the section; card per child page with photo; no thin filler. | O32: CollectionPage + BreadcrumbList | P32: - | Q32: Y | R32: index | S32: Every guide | T32: =SUMIF('Seed Keywords'!$C:$C,E32,'Seed Keywords'!$E:$E)+SUMIF('Seed Keywords'!$C:$C,E32&"#*",'Seed Keywords'!$E:$E) -> 0
A33: P032 | B33: 2 | C33: Planned | D33: Roofing service | E33: /services/shingle-roofing/ | F33: shingle roofing austin | G33: asphalt shingle roof austin; architectural shingles austin; impact resistant shingles austin | H33: Transactional | I33: Shingle Roofing in Austin, TX | Portillo Roofing | J33: =IF(LEFT(I33,1)="(","",LEN(I33)) -> 48 | K33: Shingle Roofing in Austin & Central Texas | M33: =IF(L33="","",LEN(L33)) | N33: 40-60 word direct answer up top; dated $/square range from YOUR jobs + what moves it; specs (panel profile, gauge, underlayment, impact rating); typical duration; permit office; 2+ captioned project photos; 5-8 FAQs unique to this page; last-updated date. | O33: Service (provider #org, areaServed) + BreadcrumbList; FAQPage optional (no rich result) | P33: Photos of this service + process + FAQs. Evidence: TXST Apartments | Q33: Y | R33: index | S33: Live city pages | T33: =SUMIF('Seed Keywords'!$C:$C,E33,'Seed Keywords'!$E:$E)+SUMIF('Seed Keywords'!$C:$C,E33&"#*",'Seed Keywords'!$E:$E) -> 0
A34: P033 | B34: 2 | C34: Planned | D34: Roofing service | E34: /services/tile-roof-repair/ | F34: tile roof repair austin | G34: clay tile roof repair austin; concrete tile roof repair | H34: Transactional | I34: Tile Roof Repair in Austin, TX | Portillo Roofing | J34: =IF(LEFT(I34,1)="(","",LEN(I34)) -> 49 | K34: Tile Roof Repair in Austin & Central Texas | M34: =IF(L34="","",LEN(L34)) | N34: 40-60 word direct answer up top; dated $/square range from YOUR jobs + what moves it; specs (panel profile, gauge, underlayment, impact rating); typical duration; permit office; 2+ captioned project photos; 5-8 FAQs unique to this page; last-updated date. | O34: Service (provider #org, areaServed) + BreadcrumbList; FAQPage optional (no rich result) | P34: Photos of this service + process + FAQs. Evidence: Tile repair workflow (torch-down underlayment) - need photos | Q34: ? | R34: index | S34: Live city pages; Guides: tile-roof-repair-vs-replacement | T34: =SUMIF('Seed Keywords'!$C:$C,E34,'Seed Keywords'!$E:$E)+SUMIF('Seed Keywords'!$C:$C,E34&"#*",'Seed Keywords'!$E:$E) -> 0 | U34: Underlayment-cost question is owned by the tile guide.
A35: P034 | B35: 2 | C35: Planned | D35: Roofing service | E35: /services/roof-inspection/ | F35: roof inspection austin | G35: free roof inspection austin; roof inspection for home sale | H35: Transactional | I35: Roof Inspection in Austin, TX | Portillo Roofing | J35: =IF(LEFT(I35,1)="(","",LEN(I35)) -> 48 | K35: Roof Inspection in Austin & Central Texas | M35: =IF(L35="","",LEN(L35)) | N35: 40-60 word direct answer up top; dated $/square range from YOUR jobs + what moves it; specs (panel profile, gauge, underlayment, impact rating); typical duration; permit office; 2+ captioned project photos; 5-8 FAQs unique to this page; last-updated date. | O35: Service (provider #org, areaServed) + BreadcrumbList; FAQPage optional (no rich result) | P35: Photos of this service + process + FAQs. Evidence: Listed on current site | Q35: ? | R35: index | S35: Live city pages | T35: =SUMIF('Seed Keywords'!$C:$C,E35,'Seed Keywords'!$E:$E)+SUMIF('Seed Keywords'!$C:$C,E35&"#*",'Seed Keywords'!$E:$E) -> 0
A36: P035 | B36: 2 | C36: Planned | D36: Roofing service | E36: /services/roof-coating/ | F36: roof coating austin | G36: silicone roof coating austin; elastomeric roof coating; flat roof coating austin | H36: Transactional | I36: Roof Coating in Austin, TX | Portillo Roofing | J36: =IF(LEFT(I36,1)="(","",LEN(I36)) -> 45 | K36: Silicone & Elastomeric Roof Coating in Austin & Central Texas | M36: =IF(L36="","",LEN(L36)) | N36: 40-60 word direct answer up top; dated $/square range from YOUR jobs + what moves it; specs (panel profile, gauge, underlayment, impact rating); typical duration; permit office; 2+ captioned project photos; 5-8 FAQs unique to this page; last-updated date. | O36: Service (provider #org, areaServed) + BreadcrumbList; FAQPage optional (no rich result) | P36: Photos of this service + process + FAQs. Evidence: Owner listed 'coating' - CONFIRM roof coatings specifically | Q36: ? | R36: index | S36: Live city pages | T36: =SUMIF('Seed Keywords'!$C:$C,E36,'Seed Keywords'!$E:$E)+SUMIF('Seed Keywords'!$C:$C,E36&"#*",'Seed Keywords'!$E:$E) -> 0 | U36: Offered? CONFIRM.
A37: P036 | B37: 2 | C37: Gated | D37: Trade service | E37: /remodeling/home-renovation/ | F37: home renovation austin | G37: whole house remodel austin; interior renovation contractor austin | H37: Transactional | I37: Whole-Home Interior Renovation in Austin, TX | J37: =IF(LEFT(I37,1)="(","",LEN(I37)) -> 44 | K37: Whole-Home Interior Renovation in Austin | M37: =IF(L37="","",LEN(L37)) | N37: Direct answer up top; price range from your jobs; 4+ before/after photos; scope steps; how it pairs with roofing/remodel; FAQs unique to this page; last-updated date. | O37: Service (provider #org, areaServed) + BreadcrumbList | P37: Finished job + before/after photos. Evidence: Villa Park (in progress), Dodd (quoted) - not proof until complete | Q37: N | R37: index | S37: /remodeling/; related projects | T37: =SUMIF('Seed Keywords'!$C:$C,E37,'Seed Keywords'!$E:$E)+SUMIF('Seed Keywords'!$C:$C,E37&"#*",'Seed Keywords'!$E:$E) -> 0 | U37: Category: Remodeling.
A38: P037 | B38: 2 | C38: Gated | D38: Trade service | E38: /remodeling/patio-covers/ | F38: patio cover builder austin | G38: covered patio addition austin; patio roof austin | H38: Transactional | I38: Patio Covers in Austin, TX | Portillo Roofing | J38: =IF(LEFT(I38,1)="(","",LEN(I38)) -> 45 | K38: Patio Covers & Additions in Austin | M38: =IF(L38="","",LEN(L38)) | N38: Direct answer up top; price range from your jobs; 4+ before/after photos; scope steps; how it pairs with roofing/remodel; FAQs unique to this page; last-updated date. | O38: Service (provider #org, areaServed) + BreadcrumbList | P38: Finished job + before/after photos. Evidence: Huntridge (quoted) - not proof until complete | Q38: N | R38: index | S38: /remodeling/; related projects | T38: =SUMIF('Seed Keywords'!$C:$C,E38,'Seed Keywords'!$E:$E)+SUMIF('Seed Keywords'!$C:$C,E38&"#*",'Seed Keywords'!$E:$E) -> 0 | U38: Category: Remodeling.
A39: P038 | B39: 2 | C39: Gated | D39: Trade service | E39: /remodeling/epoxy-flooring/ | F39: epoxy flooring austin | G39: garage floor coating austin; epoxy garage floor austin; polyaspartic floor coating | H39: Transactional | I39: Epoxy Floor in Austin, TX | Portillo Roofing | J39: =IF(LEFT(I39,1)="(","",LEN(I39)) -> 44 | K39: Epoxy Floor & Garage Coatings in Austin | M39: =IF(L39="","",LEN(L39)) | N39: Direct answer up top; price range from your jobs; 4+ before/after photos; scope steps; how it pairs with roofing/remodel; FAQs unique to this page; last-updated date. | O39: Service (provider #org, areaServed) + BreadcrumbList | P39: Finished job + before/after photos. Evidence: On relaunch branch - need finished-floor photos | Q39: ? | R39: index | S39: /remodeling/; related projects | T39: =SUMIF('Seed Keywords'!$C:$C,E39,'Seed Keywords'!$E:$E)+SUMIF('Seed Keywords'!$C:$C,E39&"#*",'Seed Keywords'!$E:$E) -> 0 | U39: Category: Remodeling.
A40: P039 | B40: 2 | C40: Section | D40: Section | E40: /remodeling/#kitchen | F40: kitchen remodel austin | G40: kitchen remodeling contractor austin | H40: Transactional | I40: (section - uses parent page title) | J40: =IF(LEFT(I40,1)="(","",LEN(I40)) | K40: H2: Kitchen Remodeling | M40: =IF(L40="","",LEN(L40)) | N40: Inside the parent page: H2 named for the service, 80-150 words, 2+ photos, price range or 'typical scope', link to contact. Promote to its own page when proof + volume justify it. | O40: None of its own - listed in parent page's Service / hasOfferCatalog | P40: Photos of this work. Evidence: Dissected from whole-home work | Q40: ? | R40: index | S40: Parent: /remodeling/ | T40: =SUMIF('Seed Keywords'!$C:$C,E40,'Seed Keywords'!$E:$E)+SUMIF('Seed Keywords'!$C:$C,E40&"#*",'Seed Keywords'!$E:$E) -> 0 | U40: Category: Remodeling.
...

Sheet Site Skeleton
A1: Level | B1: Surface | C1: Path pattern | D1: Count | E1: Live | F1: Draft | G1: Planned | H1: Section | I1: Gated | J1: Phase 1 | K1: Owns cluster shape | L1: Feeds (internal links) | M1: Schema
A2: 0 | B2: Home | C2: / | D2: =COUNTIF('Page Map'!$D$2:$D$126,B2) -> 1 | E2: =COUNTIFS('Page Map'!$D$2:$D$126,B2,'Page Map'!$C$2:$C$126,"Live") -> 1 | F2: =COUNTIFS('Page Map'!$D$2:$D$126,B2,'Page Map'!$C$2:$C$126,"Draft") -> 0 | G2: =COUNTIFS('Page Map'!$D$2:$D$126,B2,'Page Map'!$C$2:$C$126,"Planned") -> 0 | H2: =COUNTIFS('Page Map'!$D$2:$D$126,B2,'Page Map'!$C$2:$C$126,"Section") -> 0 | I2: =COUNTIFS('Page Map'!$D$2:$D$126,B2,'Page Map'!$C$2:$C$126,"Gated") -> 0 | J2: =COUNTIFS('Page Map'!$D$2:$D$126,B2,'Page Map'!$B$2:$B$126,1,'Page Map'!$C$2:$C$126,"<>Gated",'Page Map'!$C$2:$C$126,"<>Section") -> 1 | K2: roofing contractor austin | L2: hubs, top roofing services, projects, builders | M2: RoofingContractor + GeneralContractor (#org): foundingDate, address (Dale), telephone, areaServed [14 cities w/ Wikipedia sameAs], sameAs [GBP, BBB, Yelp, Facebook], hasOfferCatalog; WebSite
A3: 1 | B3: Static | C3: /about/ /contact/ /for-builders/ /for-restoration/ /reviews/ | D3: =COUNTIF('Page Map'!$D$2:$D$126,B3) -> 5 | E3: =COUNTIFS('Page Map'!$D$2:$D$126,B3,'Page Map'!$C$2:$C$126,"Live") -> 2 | F3: =COUNTIFS('Page Map'!$D$2:$D$126,B3,'Page Map'!$C$2:$C$126,"Draft") -> 0 | G3: =COUNTIFS('Page Map'!$D$2:$D$126,B3,'Page Map'!$C$2:$C$126,"Planned") -> 3 | H3: =COUNTIFS('Page Map'!$D$2:$D$126,B3,'Page Map'!$C$2:$C$126,"Section") -> 0 | I3: =COUNTIFS('Page Map'!$D$2:$D$126,B3,'Page Map'!$C$2:$C$126,"Gated") -> 0 | J3: =COUNTIFS('Page Map'!$D$2:$D$126,B3,'Page Map'!$B$2:$B$126,1,'Page Map'!$C$2:$C$126,"<>Gated",'Page Map'!$C$2:$C$126,"<>Section") -> 4 | K3: brand; roofing subcontractor; restoration partner | L3: projects, services | M3: AboutPage / ContactPage / Service
A4: 1 | B4: Hub | C4: /services/ /projects/ /remodeling/ /countertops/ /areas/ /guides/ | D4: =COUNTIF('Page Map'!$D$2:$D$126,B4) -> 6 | E4: =COUNTIFS('Page Map'!$D$2:$D$126,B4,'Page Map'!$C$2:$C$126,"Live") -> 1 | F4: =COUNTIFS('Page Map'!$D$2:$D$126,B4,'Page Map'!$C$2:$C$126,"Draft") -> 1 | G4: =COUNTIFS('Page Map'!$D$2:$D$126,B4,'Page Map'!$C$2:$C$126,"Planned") -> 4 | H4: =COUNTIFS('Page Map'!$D$2:$D$126,B4,'Page Map'!$C$2:$C$126,"Section") -> 0 | I4: =COUNTIFS('Page Map'!$D$2:$D$126,B4,'Page Map'!$C$2:$C$126,"Gated") -> 0 | J4: =COUNTIFS('Page Map'!$D$2:$D$126,B4,'Page Map'!$B$2:$B$126,1,'Page Map'!$C$2:$C$126,"<>Gated",'Page Map'!$C$2:$C$126,"<>Section") -> 2 | K4: category head terms | L4: child pages | M4: CollectionPage + BreadcrumbList
A5: 1 | B5: Roofing service | C5: /services/<service>/ | D5: =COUNTIF('Page Map'!$D$2:$D$126,B5) -> 13 | E5: =COUNTIFS('Page Map'!$D$2:$D$126,B5,'Page Map'!$C$2:$C$126,"Live") -> 0 | F5: =COUNTIFS('Page Map'!$D$2:$D$126,B5,'Page Map'!$C$2:$C$126,"Draft") -> 0 | G5: =COUNTIFS('Page Map'!$D$2:$D$126,B5,'Page Map'!$C$2:$C$126,"Planned") -> 12 | H5: =COUNTIFS('Page Map'!$D$2:$D$126,B5,'Page Map'!$C$2:$C$126,"Section") -> 0 | I5: =COUNTIFS('Page Map'!$D$2:$D$126,B5,'Page Map'!$C$2:$C$126,"Gated") -> 1 | J5: =COUNTIFS('Page Map'!$D$2:$D$126,B5,'Page Map'!$B$2:$B$126,1,'Page Map'!$C$2:$C$126,"<>Gated",'Page Map'!$C$2:$C$126,"<>Section") -> 7 | K5: <service> austin | L5: live towns, projects, guides | M5: Service (provider #org, areaServed) + BreadcrumbList; FAQPage optional (no rich result)
A6: 1 | B6: Trade service | C6: /remodeling/<service>/ | D6: =COUNTIF('Page Map'!$D$2:$D$126,B6) -> 3 | E6: =COUNTIFS('Page Map'!$D$2:$D$126,B6,'Page Map'!$C$2:$C$126,"Live") -> 0 | F6: =COUNTIFS('Page Map'!$D$2:$D$126,B6,'Page Map'!$C$2:$C$126,"Draft") -> 0 | G6: =COUNTIFS('Page Map'!$D$2:$D$126,B6,'Page Map'!$C$2:$C$126,"Planned") -> 0 | H6: =COUNTIFS('Page Map'!$D$2:$D$126,B6,'Page Map'!$C$2:$C$126,"Section") -> 0 | I6: =COUNTIFS('Page Map'!$D$2:$D$126,B6,'Page Map'!$C$2:$C$126,"Gated") -> 3 | J6: =COUNTIFS('Page Map'!$D$2:$D$126,B6,'Page Map'!$B$2:$B$126,1,'Page Map'!$C$2:$C$126,"<>Gated",'Page Map'!$C$2:$C$126,"<>Section") -> 0 | K6: <service> austin | L6: /remodeling/, projects | M6: Service (provider #org, areaServed) + BreadcrumbList
A7: 1 | B7: Section | C7: <parent>/#<service> | D7: =COUNTIF('Page Map'!$D$2:$D$126,B7) -> 18 | E7: =COUNTIFS('Page Map'!$D$2:$D$126,B7,'Page Map'!$C$2:$C$126,"Live") -> 0 | F7: =COUNTIFS('Page Map'!$D$2:$D$126,B7,'Page Map'!$C$2:$C$126,"Draft") -> 0 | G7: =COUNTIFS('Page Map'!$D$2:$D$126,B7,'Page Map'!$C$2:$C$126,"Planned") -> 0 | H7: =COUNTIFS('Page Map'!$D$2:$D$126,B7,'Page Map'!$C$2:$C$126,"Section") -> 18 | I7: =COUNTIFS('Page Map'!$D$2:$D$126,B7,'Page Map'!$C$2:$C$126,"Gated") -> 0 | J7: =COUNTIFS('Page Map'!$D$2:$D$126,B7,'Page Map'!$B$2:$B$126,1,'Page Map'!$C$2:$C$126,"<>Gated",'Page Map'!$C$2:$C$126,"<>Section") -> 0 | K7: <service> austin (on parent page) | L7: parent page | M7: None of its own - listed in parent page's Service / hasOfferCatalog
A8: 2 | B8: City | C8: /areas/<town>/ | D8: =COUNTIF('Page Map'!$D$2:$D$126,B8) -> 13 | E8: =COUNTIFS('Page Map'!$D$2:$D$126,B8,'Page Map'!$C$2:$C$126,"Live") -> 0 | F8: =COUNTIFS('Page Map'!$D$2:$D$126,B8,'Page Map'!$C$2:$C$126,"Draft") -> 0 | G8: =COUNTIFS('Page Map'!$D$2:$D$126,B8,'Page Map'!$C$2:$C$126,"Planned") -> 2 | H8: =COUNTIFS('Page Map'!$D$2:$D$126,B8,'Page Map'!$C$2:$C$126,"Section") -> 0 | I8: =COUNTIFS('Page Map'!$D$2:$D$126,B8,'Page Map'!$C$2:$C$126,"Gated") -> 11 | J8: =COUNTIFS('Page Map'!$D$2:$D$126,B8,'Page Map'!$B$2:$B$126,1,'Page Map'!$C$2:$C$126,"<>Gated",'Page Map'!$C$2:$C$126,"<>Section") -> 2 | K8: roofer <town>; roof repair <town> | L8: services, projects in town, nearby towns | M8: Service (provider #org, areaServed City) + BreadcrumbList. Never a separate business entity per town.
A9: 2 | B9: Project | C9: /projects/<project>/ | D9: =COUNTIF('Page Map'!$D$2:$D$126,B9) -> 10 | E9: =COUNTIFS('Page Map'!$D$2:$D$126,B9,'Page Map'!$C$2:$C$126,"Live") -> 0 | F9: =COUNTIFS('Page Map'!$D$2:$D$126,B9,'Page Map'!$C$2:$C$126,"Draft") -> 9 | G9: =COUNTIFS('Page Map'!$D$2:$D$126,B9,'Page Map'!$C$2:$C$126,"Planned") -> 0 | H9: =COUNTIFS('Page Map'!$D$2:$D$126,B9,'Page Map'!$C$2:$C$126,"Section") -> 0 | I9: =COUNTIFS('Page Map'!$D$2:$D$126,B9,'Page Map'!$C$2:$C$126,"Gated") -> 1 | J9: =COUNTIFS('Page Map'!$D$2:$D$126,B9,'Page Map'!$B$2:$B$126,1,'Page Map'!$C$2:$C$126,"<>Gated",'Page Map'!$C$2:$C$126,"<>Section") -> 5 | K9: proof | L9: service + town | M9: Article/CreativeWork (contentLocation, dateCreated, about -> Service, image[]) + BreadcrumbList
A10: 2 | B10: Guide | C10: /guides/<question>/ | D10: =COUNTIF('Page Map'!$D$2:$D$126,B10) -> 14 | E10: =COUNTIFS('Page Map'!$D$2:$D$126,B10,'Page Map'!$C$2:$C$126,"Live") -> 0 | F10: =COUNTIFS('Page Map'!$D$2:$D$126,B10,'Page Map'!$C$2:$C$126,"Draft") -> 0 | G10: =COUNTIFS('Page Map'!$D$2:$D$126,B10,'Page Map'!$C$2:$C$126,"Planned") -> 14 | H10: =COUNTIFS('Page Map'!$D$2:$D$126,B10,'Page Map'!$C$2:$C$126,"Section") -> 0 | I10: =COUNTIFS('Page Map'!$D$2:$D$126,B10,'Page Map'!$C$2:$C$126,"Gated") -> 0 | J10: =COUNTIFS('Page Map'!$D$2:$D$126,B10,'Page Map'!$B$2:$B$126,1,'Page Map'!$C$2:$C$126,"<>Gated",'Page Map'!$C$2:$C$126,"<>Section") -> 1 | K10: questions, costs, comparisons | L10: matching service | M10: Article (author Person w/ sameAs, dateModified) + BreadcrumbList
A11: 3 | B11: Service x City | C11: /areas/<town>/<service>/ | D11: =COUNTIF('Page Map'!$D$2:$D$126,B11) -> 39 | E11: =COUNTIFS('Page Map'!$D$2:$D$126,B11,'Page Map'!$C$2:$C$126,"Live") -> 0 | F11: =COUNTIFS('Page Map'!$D$2:$D$126,B11,'Page Map'!$C$2:$C$126,"Draft") -> 0 | G11: =COUNTIFS('Page Map'!$D$2:$D$126,B11,'Page Map'!$C$2:$C$126,"Planned") -> 1 | H11: =COUNTIFS('Page Map'!$D$2:$D$126,B11,'Page Map'!$C$2:$C$126,"Section") -> 0 | I11: =COUNTIFS('Page Map'!$D$2:$D$126,B11,'Page Map'!$C$2:$C$126,"Gated") -> 38 | J11: =COUNTIFS('Page Map'!$D$2:$D$126,B11,'Page Map'!$B$2:$B$126,1,'Page Map'!$C$2:$C$126,"<>Gated",'Page Map'!$C$2:$C$126,"<>Section") -> 0 | K11: <service> <town> | L11: town, service, project | M11: Service (provider #org, areaServed City) + BreadcrumbList
A12: 9 | B12: Utility | C12: /thank-you/ /privacy-policy/ /terms-of-service/ | D12: =COUNTIF('Page Map'!$D$2:$D$126,B12) -> 3 | E12: =COUNTIFS('Page Map'!$D$2:$D$126,B12,'Page Map'!$C$2:$C$126,"Live") -> 3 | F12: =COUNTIFS('Page Map'!$D$2:$D$126,B12,'Page Map'!$C$2:$C$126,"Draft") -> 0 | G12: =COUNTIFS('Page Map'!$D$2:$D$126,B12,'Page Map'!$C$2:$C$126,"Planned") -> 0 | H12: =COUNTIFS('Page Map'!$D$2:$D$126,B12,'Page Map'!$C$2:$C$126,"Section") -> 0 | I12: =COUNTIFS('Page Map'!$D$2:$D$126,B12,'Page Map'!$C$2:$C$126,"Gated") -> 0 | J12: =COUNTIFS('Page Map'!$D$2:$D$126,B12,'Page Map'!$B$2:$B$126,1,'Page Map'!$C$2:$C$126,"<>Gated",'Page Map'!$C$2:$C$126,"<>Section") -> 3 | K12: - | L12: - | M12: -
B13: Total | D13: =SUM(D2:D12) -> 125 | E13: =SUM(E2:E12) -> 7 | F13: =SUM(F2:F12) -> 10 | G13: =SUM(G2:G12) -> 36 | H13: =SUM(H2:H12) -> 18 | I13: =SUM(I2:I12) -> 54 | J13: =SUM(J2:J12) -> 25
B15: Phase 1 = pages to build in the first pass (excludes Gated and Section rows; includes Live pages that get reworked).

Sheet Services
A1: Category | B1: Slug | C1: Service | D1: Primary keyword | E1: Lives at | F1: Offered? (confirm) | G1: Evidence | H1: Phase | I1: Status
A2: Roofing | B2: roof-replacement | C2: Roof Replacement | D2: roof replacement austin | E2: /services/roof-replacement/ | F2: Y | G2: TXST Apartments (400 sq reroof) | H2: 1 | I2: Planned
A3: Roofing | B3: roof-repair | C3: Roof Repair | D3: roof repair austin | E3: /services/roof-repair/ | F3: Y | G3: Listed on current site - need repair job photos | H3: 1 | I3: Planned
A4: Roofing | B4: metal-roofing | C4: Standing Seam Metal Roofing | D4: metal roofing austin | E4: /services/metal-roofing/ | F4: Y | G4: Inwood, Shoalwood, Knollwood, Curved Ridges, Yuapon | H4: 1 | I4: Planned
A5: Roofing | B5: flat-roofing | C5: Flat & TPO Roofing | D5: tpo roofing austin | E5: /services/flat-roofing/ | F5: Y | G5: Mendez School (TPO), Knollwood | H5: 1 | I5: Planned
A6: Roofing | B6: commercial-roofing | C6: Commercial Roofing | D6: commercial roofing austin | E6: /services/commercial-roofing/ | F6: Y | G6: Travis County Jail, Mendez School, TXST, UT Batter's Eye | H6: 1 | I6: Planned
A7: Roofing | B7: new-construction-roofing | C7: New Construction Roofing | D7: new construction roofing austin | E7: /services/new-construction-roofing/ | F7: Y | G7: Inwood, Shoalwood, Knollwood, Fiset | H7: 1 | I7: Planned
A8: Roofing | B8: hail-damage-roof-repair | C8: Hail & Storm Damage Repair | D8: hail damage roof repair austin | E8: /services/hail-damage-roof-repair/ | F8: Y | G8: Listed on current site - need storm job photos | H8: 1 | I8: Planned
A9: Roofing | B9: shingle-roofing | C9: Shingle Roofing | D9: shingle roofing austin | E9: /services/shingle-roofing/ | F9: Y | G9: TXST Apartments | H9: 2 | I9: Planned
A10: Roofing | B10: tile-roof-repair | C10: Tile Roof Repair | D10: tile roof repair austin | E10: /services/tile-roof-repair/ | F10: Y | G10: Tile repair workflow (torch-down underlayment) - need photos | H10: 2 | I10: Planned
A11: Roofing | B11: roof-inspection | C11: Roof Inspection | D11: roof inspection austin | E11: /services/roof-inspection/ | F11: Y | G11: Listed on current site | H11: 2 | I11: Planned
A12: Roofing | B12: roof-coating | C12: Silicone & Elastomeric Roof Coating | D12: roof coating austin | E12: /services/roof-coating/ | F12: ? | G12: Owner listed 'coating' - CONFIRM roof coatings specifically | H12: 2 | I12: Planned
A13: Roofing | B13: gutters | C13: Gutters | D13: gutter installation austin | E13: /services/gutters/ | F13: ? | G13: Travis County Jail scope included gutters - CONFIRM standalone | H13: 3 | I13: Planned
... A35: Countertops | B35: countertop-resurfacing | C35: Countertop Resurfacing | D35: countertop resurfacing austin | E35: /countertops/#resurfacing | F35: ? | G35: CONFIRM offered | H35: 3 | I35: Section

Sheet Service Areas
A1: Slug | B1: Town | C1: County | D1: Drive from Dale (min, est.) | E1: Zone | F1: What we take on (zone rule) | G1: Min job size (you set) | H1: Phase | I1: Completed jobs here (fill in) | J1: Pages generated | K1: Town page status
A2: (austin) | B2: Austin | C2: Travis (also Williamson, Hays) | D2: 40 | E2: Metro | F2: Covered by home + service pages; no town page | H2: 1 | I2: Villa Park, Huntridge (in progress/quoted) | J2: - | K2: -
A3: dale | B3: Dale | C3: Caldwell | D3: 0 | E3: South core | F3: All services incl. add-ons | H3: 1 | J3: =COUNTIF('Page Map'!$E$2:$E$126,"/areas/"&A3&"/*") -> 4 | K3: =IF(I3="","Gated - needs a job","Ready to build") -> Gated - needs a job
A4: san-marcos | B4: San Marcos | C4: Hays (also Caldwell/Guadalupe) | D4: 35 | E4: South core | F4: All services incl. add-ons | H4: 1 | J4: =COUNTIF('Page Map'!$E$2:$E$126,"/areas/"&A4&"/*") -> 4 | K4: =IF(I4="","Gated - needs a job","Ready to build") -> Gated - needs a job
A5: lockhart | B5: Lockhart | C5: Caldwell | D5: 15 | E5: South core | F5: All services incl. add-ons | H5: 2 | J5: =COUNTIF('Page Map'!$E$2:$E$126,"/areas/"&A5&"/*") -> 4 | K5: =IF(I5="","Gated - needs a job","Ready to build") -> Gated - needs a job
A6: bastrop | B6: Bastrop | C6: Bastrop | D6: 30 | E6: South core | F6: All services incl. add-ons | H6: 2 | J6: =COUNTIF('Page Map'!$E$2:$E$126,"/areas/"&A6&"/*") -> 4 | K6: =IF(I6="","Gated - needs a job","Ready to build") -> Gated - needs a job
A7: kyle | B7: Kyle | C7: Hays | D7: 35 | E7: South core | F7: All services incl. add-ons | H7: 2 | J7: =COUNTIF('Page Map'!$E$2:$E$126,"/areas/"&A7&"/*") -> 4 | K7: =IF(I7="","Gated - needs a job","Ready to build") -> Gated - needs a job
A8: buda | B8: Buda | C8: Hays | D8: 40 | E8: South core | F8: All services incl. add-ons | H8: 2 | J8: =COUNTIF('Page Map'!$E$2:$E$126,"/areas/"&A8&"/*") -> 4 | K8: =IF(I8="","Gated - needs a job","Ready to build") -> Gated - needs a job
A9: manor | B9: Manor | C9: Travis | D9: 50 | E9: East / metro | F9: Roofing + remodeling; no low-ticket add-ons | H9: 3 | J9: =COUNTIF('Page Map'!$E$2:$E$126,"/areas/"&A9&"/*") -> 4 | K9: =IF(I9="","Gated - needs a job","Ready to build") -> Gated - needs a job
A10: pflugerville | B10: Pflugerville | C10: Travis (also Williamson) | D10: 55 | E10: East / metro | F10: Roofing + remodeling; no low-ticket add-ons | H10: 3 | J10: =COUNTIF('Page Map'!$E$2:$E$126,"/areas/"&A10&"/*") -> 4 | K10: =IF(I10="","Gated - needs a job","Ready to build") -> Gated - needs a job
A11: round-rock | B11: Round Rock | C11: Williamson (also Travis) | D11: 60 | E11: North | F11: Roofing replacement, metal, commercial, new construction only | G11: suggested: $8k+ | H11: 3 | J11: =COUNTIF('Page Map'!$E$2:$E$126,"/areas/"&A11&"/*") -> 4 | K11: =IF(I11="","Gated - needs a job","Ready to build") -> Gated - needs a job
A12: hutto | B12: Hutto | C12: Williamson | D12: 60 | E12: North | F12: Roofing replacement, metal, commercial, new construction only | G12: suggested: $8k+ | H12: 3 | J12: =COUNTIF('Page Map'!$E$2:$E$126,"/areas/"&A12&"/*") -> 4 | K12: =IF(I12="","Gated - needs a job","Ready to build") -> Gated - needs a job
A13: cedar-park | B13: Cedar Park | C13: Williamson (also Travis) | D13: 70 | E13: North | F13: Roofing replacement, metal, commercial, new construction only | G13: suggested: $8k+ | H13: 3 | J13: =COUNTIF('Page Map'!$E$2:$E$126,"/areas/"&A13&"/*") -> 4 | K13: =IF(I13="","Gated - needs a job","Ready to build") -> Gated - needs a job
A14: leander | B14: Leander | C14: Williamson (also Travis) | D14: 75 | E14: North | F14: Roofing replacement, metal, commercial, new construction only | G14: suggested: $8k+ | H14: 3 | J14: =COUNTIF('Page Map'!$E$2:$E$126,"/areas/"&A14&"/*") -> 4 | K14: =IF(I14="","Gated - needs a job","Ready to build") -> Gated - needs a job
A15: georgetown | B15: Georgetown | C15: Williamson | D15: 75 | E15: North | F15: Roofing replacement, metal, commercial, new construction only | G15: suggested: $8k+ | H15: 3 | J15: =COUNTIF('Page Map'!$E$2:$E$126,"/areas/"&A15&"/*") -> 4 | K15: =IF(I15="","Gated - needs a job","Ready to build") -> Gated - needs a job
A17: Drive times are off-peak estimates from Dale. Min job size is a council suggestion for north-zone towns - set your own.

Sheet Seed Keywords
A1: Keyword (paste into Planner) | B1: Surface | C1: Target path | D1: Note | E1: Avg monthly searches | F1: Competition | G1: Top-of-page bid low ($) | H1: Top-of-page bid high ($)
A2: roofing contractor austin | B2: Home | C2: /
A3: roofing company austin | B3: Home | C3: /
A4: roofers austin tx | B4: Home | C4: /
A5: best roofing company austin | B5: Home | C5: / | D5: Map-pack / GBP-driven - a page can't 'own' this; tracks demand only
A6: roofers near me | B6: GBP-driven | C6: / | D6: Map-pack / GBP-driven - a page can't 'own' this; tracks demand only
A7: roofing companies near me | B7: GBP-driven | C7: / | D7: Map-pack / GBP-driven - a page can't 'own' this; tracks demand only
A8: roof repair near me | B8: GBP-driven | C8: /services/roof-repair/ | D8: Map-pack / GBP-driven - a page can't 'own' this; tracks demand only
A9: roof replacement near me | B9: GBP-driven | C9: /services/roof-replacement/ | D9: Map-pack / GBP-driven - a page can't 'own' this; tracks demand only
A10: metal roofing contractors near me | B10: GBP-driven | C10: /services/metal-roofing/ | D10: Map-pack / GBP-driven - a page can't 'own' this; tracks demand only
A11: remodeling contractors near me | B11: GBP-driven | C11: /remodeling/ | D11: Map-pack / GBP-driven - a page can't 'own' this; tracks demand only
A12: pressure washing near me | B12: GBP-driven | C12: /remodeling/#pressure-washing | D12: Map-pack / GBP-driven - a page can't 'own' this; tracks demand only
A13: countertop installers near me | B13: GBP-driven | C13: /countertops/ | D13: Map-pack / GBP-driven - a page can't 'own' this; tracks demand only
A14: roofing subcontractor austin | B14: Static | C14: /for-builders/
A15: roofing subcontractor | B15: Static | C15: /for-builders/
A16: restoration roofing subcontractor austin | B16: Static | C16: /for-restoration/
A17: roofing services austin | B17: Hub | C17: /services/
A18: remodeling contractor austin | B18: Hub | C18: /remodeling/
A19: custom countertops austin | B19: Hub | C19: /countertops/
A20: pressure washing austin | B20: Section | C20: /remodeling/#pressure-washing
A21: power washing austin | B21: Section | C21: /remodeling/#pressure-washing
A22: roof replacement austin | B22: Roofing service | C22: /services/roof-replacement/
A23: roof replacement austin tx | B23: Roofing service | C23: /services/roof-replacement/
